<?xml version="1.0" ?>
<!-- =================================================================================== -->
<!-- |    This document was autogenerated by xacro from /home/ubb/Documents/VR_galactic/install/t42_gripper_description/share/t42_gripper_description/urdf/t42_hand.xacro | -->
<!-- |    EDITING THIS FILE BY HAND IS NOT RECOMMENDED                                 | -->
<!-- =================================================================================== -->
<robot name="t42_gripper">
  <link name="world"/>
  <joint name="world_to_gripper" type="fixed">
    <origin rpy="0 0 0" xyz="0 0 0.0"/>
    <parent link="world"/>
    <child link="t42_base_link"/>
  </joint>
  <ros2_control name="TR42PositionHardwareInterface" type="system">
    <hardware>
      <plugin>fake_components/GenericSystem</plugin>
      <!-- <xacro:unless value="${use_fake_hardware}">
          <plugin>ur_robot_driver/URPositionHardwareInterface</plugin>
        </xacro:unless> -->
    </hardware>
    <joint name="swivel_2_to_finger_2_1">
      <command_interface name="position">
        <param name="min">0</param>
        <param name="max">1.57</param>
      </command_interface>
      <command_interface name="velocity">
        <param name="min">-2</param>
        <param name="max">2</param>
      </command_interface>
      <state_interface name="position"/>
      <state_interface name="velocity"/>
      <state_interface name="effort"/>
      <param name="initial_position">0.0</param>
      <!-- initial position for the FakeSystem -->
    </joint>
    <joint name="finger_2_1_to_finger_2_2">
      <command_interface name="position">
        <param name="min">0</param>
        <param name="max">1.57</param>
      </command_interface>
      <command_interface name="velocity">
        <param name="min">-2</param>
        <param name="max">2</param>
      </command_interface>
      <state_interface name="position"/>
      <state_interface name="velocity"/>
      <state_interface name="effort"/>
      <param name="initial_position">0.0</param>
      <!-- initial position for the FakeSystem -->
    </joint>
    <joint name="swivel_1_to_finger_1_1">
      <command_interface name="position">
        <param name="min">0</param>
        <param name="max">1.57</param>
      </command_interface>
      <command_interface name="velocity">
        <param name="min">-2</param>
        <param name="max">2</param>
      </command_interface>
      <state_interface name="position"/>
      <state_interface name="velocity"/>
      <state_interface name="effort"/>
      <param name="initial_position">0.0</param>
      <!-- initial position for the FakeSystem -->
    </joint>
    <joint name="finger_1_1_to_finger_1_2">
      <command_interface name="position">
        <param name="min">0</param>
        <param name="max">1.57</param>
      </command_interface>
      <command_interface name="velocity">
        <param name="min">-2</param>
        <param name="max">2</param>
      </command_interface>
      <state_interface name="position"/>
      <state_interface name="velocity"/>
      <state_interface name="effort"/>
      <param name="initial_position">0.0</param>
      <!-- initial position for the FakeSystem -->
    </joint>
  </ros2_control>
  <link name="t42_base_link">
    <visual>
      <origin rpy="0 0 1.57" xyz="0.1 -0.035 -0.09"/>
      <geometry>
        <mesh filename="/home/ubb/Documents/VR_galactic/src/t42_gripper/t42_gripper_description/meshes/actuator_block_t42.stl"/>
      </geometry>
      <material name="black">
        <color rgba="0.1 0.1 0.1 1"/>
      </material>
    </visual>
    <!-- <inertial>
            <origin xyz="0 0 0" rpy="0 0 0"/>
            <mass value="0.1"/>
            <inertia
            ixx="0.0" ixy="0.0" ixz="0.0"
            iyy="0.0" iyz="0.0"
            izz="0.0"/>
        </inertial> -->
    <collision>
      <origin rpy="0 0 1.57" xyz="0.1 -0.035 -0.09"/>
      <geometry>
        <mesh filename="/home/ubb/Documents/VR_galactic/src/t42_gripper/t42_gripper_description/meshes/actuator_block_t42.stl"/>
      </geometry>
    </collision>
  </link>
  <link name="swivel_1">
    <visual>
      <material name="white">
        <color rgba="1.0 1.0 1.0 1.0"/>
      </material>
      <origin rpy="0 1.57 1.57" xyz="-0.016510 0.026 0"/>
      <geometry>
        <mesh filename="/home/ubb/Documents/VR_galactic/src/t42_gripper/t42_gripper_description/meshes/swivel_t42.STL" scale="0.001 0.001 0.001"/>
      </geometry>
    </visual>
    <collision>
      <origin rpy="0 1.57 1.57" xyz="-0.016510 0.026 0"/>
      <geometry>
        <mesh filename="/home/ubb/Documents/VR_galactic/src/t42_gripper/t42_gripper_description/meshes/swivel_t42.STL" scale="0.001 0.001 0.001"/>
      </geometry>
    </collision>
  </link>
  <link name="finger_1_1">
    <inertial>
      <origin xyz="-0.015875 -0.009000 -0.071550"/>
      <mass value="0.1"/>
      <!-- 0.018485 -->
      <inertia ixx="0.01" ixy="0.0" ixz="0.0" iyy="0.01" iyz="0.0" izz="0.01"/>
    </inertial>
    <visual>
      <material name="white">
        <color rgba="1.0 1.0 1.0 1.0"/>
      </material>
      <origin xyz="-0.015875 -0.009000 -0.071550"/>
      <geometry>
        <mesh filename="/home/ubb/Documents/VR_galactic/src/t42_gripper/t42_gripper_description/meshes/proximal_t42.STL" scale="0.025400 0.025400 0.025400"/>
      </geometry>
    </visual>
    <collision>
      <origin xyz="-0.015875 -0.009000 -0.071550"/>
      <geometry>
        <mesh filename="/home/ubb/Documents/VR_galactic/src/t42_gripper/t42_gripper_description/meshes/proximal_t42.STL" scale="0.025400 0.025400 0.025400"/>
      </geometry>
    </collision>
  </link>
  <link name="finger_1_2">
    <inertial>
      <origin xyz="-0.015875 -0.011709 -0.048006"/>
      <mass value="0.1"/>
      <!-- 0.02369 -->
      <inertia ixx="0.01" ixy="0.0" ixz="0.0" iyy="0.01" iyz="0.0" izz="0.01"/>
    </inertial>
    <visual>
      <material name="green">
        <color rgba="0.1 1.0 0.1 1.0"/>
      </material>
      <origin xyz="-0.015875 -0.011709 -0.048006"/>
      <!-- Pointed distal tips -->
      <geometry>
        <mesh filename="/home/ubb/Documents/VR_galactic/src/t42_gripper/t42_gripper_description/meshes/distal_round_t42_filled.STL" scale="0.001 0.001 0.001"/>
        <!-- <mesh filename="/home/ubb/Documents/VR_galactic/src/t42_gripper/t42_gripper_description/meshes/distal_t42.STL" scale="0.025400 0.025400 0.025400" /> -->
        <!-- Pointed distal tips -->
      </geometry>
    </visual>
    <collision>
      <origin xyz="-0.015875 -0.011709 -0.048006"/>
      <!-- Pointed distal tips -->
      <geometry>
        <mesh filename="/home/ubb/Documents/VR_galactic/src/t42_gripper/t42_gripper_description/meshes/distal_round_t42_filled.STL" scale="0.001 0.001 0.001"/>
      </geometry>
    </collision>
  </link>
  <link name="swivel_2">
    <visual>
      <material name="white">
        <color rgba="1.0 1.0 1.0 1.0"/>
      </material>
      <origin rpy="0 1.57 1.57" xyz="-0.016510 -0.026 0"/>
      <geometry>
        <mesh filename="/home/ubb/Documents/VR_galactic/src/t42_gripper/t42_gripper_description/meshes/swivel_t42.STL" scale="0.001 0.001 0.001"/>
      </geometry>
    </visual>
    <collision>
      <origin rpy="0 1.57 1.57" xyz="-0.016510 -0.026 0"/>
      <geometry>
        <mesh filename="/home/ubb/Documents/VR_galactic/src/t42_gripper/t42_gripper_description/meshes/swivel_t42.STL" scale="0.001 0.001 0.001"/>
      </geometry>
    </collision>
  </link>
  <link name="finger_2_1">
    <inertial>
      <origin xyz="-0.015875 -0.009000 -0.071550"/>
      <mass value="0.1"/>
      <inertia ixx="0.01" ixy="0.0" ixz="0.0" iyy="0.01" iyz="0.0" izz="0.01"/>
    </inertial>
    <visual>
      <material name="white">
        <color rgba="1.0 1.0 1.0 1.0"/>
      </material>
      <origin xyz="-0.015875 -0.009000 -0.071550"/>
      <geometry>
        <mesh filename="/home/ubb/Documents/VR_galactic/src/t42_gripper/t42_gripper_description/meshes/proximal_t42.STL" scale="0.025400 0.025400 0.025400"/>
      </geometry>
    </visual>
    <collision>
      <origin xyz="-0.015875 -0.009000 -0.071550"/>
      <geometry>
        <mesh filename="/home/ubb/Documents/VR_galactic/src/t42_gripper/t42_gripper_description/meshes/proximal_t42.STL" scale="0.025400 0.025400 0.025400"/>
      </geometry>
    </collision>
  </link>
  <link name="finger_2_2">
    <inertial>
      <origin xyz="-0.015875 -0.011709 -0.048006"/>
      <mass value="0.1"/>
      <inertia ixx="0.01" ixy="0.0" ixz="0.0" iyy="0.01" iyz="0.0" izz="0.01"/>
    </inertial>
    <visual>
      <material name="orange">
        <color rgba="0.9 0.3 0.1 1.0"/>
      </material>
      <origin xyz="-0.015875 -0.011709 -0.048006"/>
      <geometry>
        <mesh filename="/home/ubb/Documents/VR_galactic/src/t42_gripper/t42_gripper_description/meshes/distal_round_t42_filled.STL" scale="0.001 0.001 0.001"/>
      </geometry>
    </visual>
    <collision>
      <origin xyz="-0.015875 -0.011709 -0.048006"/>
      <geometry>
        <mesh filename="/home/ubb/Documents/VR_galactic/src/t42_gripper/t42_gripper_description/meshes/distal_round_t42_filled.STL" scale="0.001 0.001 0.001"/>
      </geometry>
    </collision>
  </link>
  <joint name="t42_base_link_to_swivel_1" type="fixed">
    <origin rpy="0 0 0" xyz="0 0.000000 0.000000"/>
    <parent link="t42_base_link"/>
    <child link="swivel_1"/>
  </joint>
  <joint name="swivel_1_to_finger_1_1" type="revolute">
    <origin rpy="-1.57079632679 1.57079632679 0" xyz="-0.016510 -0.026 0.000000"/>
    <parent link="swivel_1"/>
    <child link="finger_1_1"/>
    <limit effort="10000" lower="0.0" upper="2" velocity="2"/>
    <axis xyz="1 0 0"/>
    <dynamics damping="7.0" friction="0.0"/>
  </joint>
  <joint name="finger_1_1_to_finger_1_2" type="revolute">
    <origin rpy="0 0 0" xyz="0.000000 0.000000 -0.062551"/>
    <parent link="finger_1_1"/>
    <child link="finger_1_2"/>
    <limit effort="10000" lower="0.0" upper="1.57" velocity="2"/>
    <axis xyz="1 0 0"/>
    <dynamics damping="7.0" friction="0.0"/>
  </joint>
  <joint name="t42_base_link_to_swivel_2" type="fixed">
    <origin rpy="0 0 0" xyz="0 0.000000 0.000000"/>
    <parent link="t42_base_link"/>
    <child link="swivel_2"/>
  </joint>
  <joint name="swivel_2_to_finger_2_1" type="revolute">
    <origin rpy="1.57079632679 -1.57079632679 0" xyz="-0.016510 0.026 0.0000"/>
    <parent link="swivel_2"/>
    <child link="finger_2_1"/>
    <limit effort="10000" lower="0.0" upper="2" velocity="2"/>
    <axis xyz="1 0 0"/>
    <dynamics damping="7.0" friction="0.0"/>
  </joint>
  <joint name="finger_2_1_to_finger_2_2" type="revolute">
    <origin rpy="0 0 0" xyz="0.000000 0.000000 -0.062551"/>
    <parent link="finger_2_1"/>
    <child link="finger_2_2"/>
    <limit effort="10000" lower="0.0" upper="1.57" velocity="2"/>
    <axis xyz="1 0 0"/>
    <dynamics damping="7.0" friction="0.0"/>
  </joint>
  <!-- Transmissions



  <transmission name="finger1_2_trans" type="SimpleTransmission">
      <type>transmission_interface/SimpleTransmission</type>
      <actuator name="$finger12_motor">
          <mechanicalReduction>1</mechanicalReduction>
      </actuator>
      <joint name="base_to_finger_1_1">
          <hardwareInterface>hardware_interface/EffortJointInterface</hardwareInterface>
      </joint>
  </transmission>

  <transmission name="finger1_3_trans" type="SimpleTransmission">
      <type>transmission_interface/SimpleTransmission</type>
      <actuator name="$finger13_motor">
          <mechanicalReduction>1</mechanicalReduction>
      </actuator>
      <joint name="finger_1_1_to_finger_1_2">
          <hardwareInterface>hardware_interface/EffortJointInterface</hardwareInterface>
      </joint>
  </transmission>

  <transmission name="finger2_2_trans" type="SimpleTransmission">
      <type>transmission_interface/SimpleTransmission</type>
      <actuator name="$finger22_motor">
          <mechanicalReduction>1</mechanicalReduction>
      </actuator>
      <joint name="base_to_finger_2_1">
          <hardwareInterface>hardware_interface/EffortJointInterface</hardwareInterface>
      </joint>
  </transmission>

  <transmission name="finger2_3_trans" type="SimpleTransmission">
      <type>transmission_interface/SimpleTransmission</type>
      <actuator name="$finger23_motor">
          <mechanicalReduction>1</mechanicalReduction>
      </actuator>
      <joint name="finger_2_1_to_finger_2_2">
          <hardwareInterface>hardware_interface/EffortJointInterface</hardwareInterface>
      </joint>
  </transmission> -->
</robot>
